INFO:root:(0 points) os.path.isfile("ex5.R") is True
INFO:root:Executed R('x1 = c(10000, 1:999)')
INFO:root:Executed R('x2 = c(1:900, rep(NA, 100))')
INFO:root:Executed R('x3 = c(1:800, rep(NA, 200))')
INFO:root:Executed R('y  = c(1:999, NA)')
INFO:root:Executed R('naR = 0.5; naC = 0.05')
INFO:root:Executed R('data = data.frame(X1=x1, X2=x2, X3=x3, X4=y, X5=y, X6=y, X7=y, X8=y, X9=y, X10=y)')
INFO:root:Executed R('cleanData = data[-c(1,1000), -c(2,3)]')
INFO:root:Executed R('dfDiag = dfDiagnosis(data, naRow=naR, naCol=naC)')
ERROR:root:Got exception on main handler
Traceback (most recent call last):
  File "/home/grader/grade/133/hiro722722/final/check.py", line 60, in run
    exec(command, g)
  File "<string>", line 1, in <module>
  File "/usr/lib64/python2.7/site-packages/rpy2/robjects/__init__.py", line 240, in __call__
    res = self.eval(p)
  File "/usr/lib64/python2.7/site-packages/rpy2/robjects/functions.py", line 86, in __call__
    return super(SignatureTranslatedFunction, self).__call__(*args, **kwargs)
  File "/usr/lib64/python2.7/site-packages/rpy2/robjects/functions.py", line 35, in __call__
    res = super(Function, self).__call__(*new_args, **new_kwargs)
RRuntimeError: Error in eval(expr, envir, enclos) : 
  could not find function "dfDiagnosis"

ERROR:root:Traceback (most recent call last):
  File "/home/grader/grade/133/hiro722722/final/check.py", line 60, in run
    exec(command, g)
  File "<string>", line 1, in <module>
  File "/usr/lib64/python2.7/site-packages/rpy2/robjects/__init__.py", line 240, in __call__
    res = self.eval(p)
  File "/usr/lib64/python2.7/site-packages/rpy2/robjects/functions.py", line 86, in __call__
    return super(SignatureTranslatedFunction, self).__call__(*args, **kwargs)
  File "/usr/lib64/python2.7/site-packages/rpy2/robjects/functions.py", line 35, in __call__
    res = super(Function, self).__call__(*new_args, **new_kwargs)
RRuntimeError: Error in eval(expr, envir, enclos) : 
  could not find function "dfDiagnosis"

Traceback (most recent call last):
  File "/home/grader/grade/133/hiro722722/final/check.py", line 60, in run
    exec(command, g)
  File "<string>", line 1, in <module>
  File "/usr/lib64/python2.7/site-packages/rpy2/robjects/__init__.py", line 240, in __call__
    res = self.eval(p)
  File "/usr/lib64/python2.7/site-packages/rpy2/robjects/functions.py", line 86, in __call__
    return super(SignatureTranslatedFunction, self).__call__(*args, **kwargs)
  File "/usr/lib64/python2.7/site-packages/rpy2/robjects/functions.py", line 35, in __call__
    res = super(Function, self).__call__(*new_args, **new_kwargs)
RRuntimeError: Error in eval(expr, envir, enclos) : 
  could not find function "dfDiagnosis"

ERROR:root:(3 points) Checking R('all.equal(class(dfDiag), \'dfDiagnosis\')')[0]
ERROR:root:... Expecting: True
ERROR:root:... But got:   Traceback error
ERROR:root:Got exception:
Traceback (most recent call last):
  File "/home/grader/grade/133/hiro722722/final/check.py", line 76, in check
    result = eval(command, g)
  File "<string>", line 1, in <module>
  File "/usr/lib64/python2.7/site-packages/rpy2/robjects/__init__.py", line 240, in __call__
    res = self.eval(p)
  File "/usr/lib64/python2.7/site-packages/rpy2/robjects/functions.py", line 86, in __call__
    return super(SignatureTranslatedFunction, self).__call__(*args, **kwargs)
  File "/usr/lib64/python2.7/site-packages/rpy2/robjects/functions.py", line 35, in __call__
    res = super(Function, self).__call__(*new_args, **new_kwargs)
RRuntimeError: Error in all.equal(class(dfDiag), "dfDiagnosis") : 
  object 'dfDiag' not found

ERROR:root:Traceback (most recent call last):
  File "/home/grader/grade/133/hiro722722/final/check.py", line 76, in check
    result = eval(command, g)
  File "<string>", line 1, in <module>
  File "/usr/lib64/python2.7/site-packages/rpy2/robjects/__init__.py", line 240, in __call__
    res = self.eval(p)
  File "/usr/lib64/python2.7/site-packages/rpy2/robjects/functions.py", line 86, in __call__
    return super(SignatureTranslatedFunction, self).__call__(*args, **kwargs)
  File "/usr/lib64/python2.7/site-packages/rpy2/robjects/functions.py", line 35, in __call__
    res = super(Function, self).__call__(*new_args, **new_kwargs)
RRuntimeError: Error in all.equal(class(dfDiag), "dfDiagnosis") : 
  object 'dfDiag' not found

Traceback (most recent call last):
  File "/home/grader/grade/133/hiro722722/final/check.py", line 76, in check
    result = eval(command, g)
  File "<string>", line 1, in <module>
  File "/usr/lib64/python2.7/site-packages/rpy2/robjects/__init__.py", line 240, in __call__
    res = self.eval(p)
  File "/usr/lib64/python2.7/site-packages/rpy2/robjects/functions.py", line 86, in __call__
    return super(SignatureTranslatedFunction, self).__call__(*args, **kwargs)
  File "/usr/lib64/python2.7/site-packages/rpy2/robjects/functions.py", line 35, in __call__
    res = super(Function, self).__call__(*new_args, **new_kwargs)
RRuntimeError: Error in all.equal(class(dfDiag), "dfDiagnosis") : 
  object 'dfDiag' not found

ERROR:root:(3 points) Checking R('all.equal(length(dfDiag), 6)')[0]
ERROR:root:... Expecting: True
ERROR:root:... But got:   Traceback error
ERROR:root:Got exception:
Traceback (most recent call last):
  File "/home/grader/grade/133/hiro722722/final/check.py", line 76, in check
    result = eval(command, g)
  File "<string>", line 1, in <module>
  File "/usr/lib64/python2.7/site-packages/rpy2/robjects/__init__.py", line 240, in __call__
    res = self.eval(p)
  File "/usr/lib64/python2.7/site-packages/rpy2/robjects/functions.py", line 86, in __call__
    return super(SignatureTranslatedFunction, self).__call__(*args, **kwargs)
  File "/usr/lib64/python2.7/site-packages/rpy2/robjects/functions.py", line 35, in __call__
    res = super(Function, self).__call__(*new_args, **new_kwargs)
RRuntimeError: Error in all.equal(length(dfDiag), 6) : object 'dfDiag' not found

ERROR:root:Traceback (most recent call last):
  File "/home/grader/grade/133/hiro722722/final/check.py", line 76, in check
    result = eval(command, g)
  File "<string>", line 1, in <module>
  File "/usr/lib64/python2.7/site-packages/rpy2/robjects/__init__.py", line 240, in __call__
    res = self.eval(p)
  File "/usr/lib64/python2.7/site-packages/rpy2/robjects/functions.py", line 86, in __call__
    return super(SignatureTranslatedFunction, self).__call__(*args, **kwargs)
  File "/usr/lib64/python2.7/site-packages/rpy2/robjects/functions.py", line 35, in __call__
    res = super(Function, self).__call__(*new_args, **new_kwargs)
RRuntimeError: Error in all.equal(length(dfDiag), 6) : object 'dfDiag' not found

Traceback (most recent call last):
  File "/home/grader/grade/133/hiro722722/final/check.py", line 76, in check
    result = eval(command, g)
  File "<string>", line 1, in <module>
  File "/usr/lib64/python2.7/site-packages/rpy2/robjects/__init__.py", line 240, in __call__
    res = self.eval(p)
  File "/usr/lib64/python2.7/site-packages/rpy2/robjects/functions.py", line 86, in __call__
    return super(SignatureTranslatedFunction, self).__call__(*args, **kwargs)
  File "/usr/lib64/python2.7/site-packages/rpy2/robjects/functions.py", line 35, in __call__
    res = super(Function, self).__call__(*new_args, **new_kwargs)
RRuntimeError: Error in all.equal(length(dfDiag), 6) : object 'dfDiag' not found

ERROR:root:(3 points) Checking R('all.equal(dfDiag$rawData, data)')[0]
ERROR:root:... Expecting: True
ERROR:root:... But got:   Traceback error
ERROR:root:Got exception:
Traceback (most recent call last):
  File "/home/grader/grade/133/hiro722722/final/check.py", line 76, in check
    result = eval(command, g)
  File "<string>", line 1, in <module>
  File "/usr/lib64/python2.7/site-packages/rpy2/robjects/__init__.py", line 240, in __call__
    res = self.eval(p)
  File "/usr/lib64/python2.7/site-packages/rpy2/robjects/functions.py", line 86, in __call__
    return super(SignatureTranslatedFunction, self).__call__(*args, **kwargs)
  File "/usr/lib64/python2.7/site-packages/rpy2/robjects/functions.py", line 35, in __call__
    res = super(Function, self).__call__(*new_args, **new_kwargs)
RRuntimeError: Error in all.equal(dfDiag$rawData, data) : object 'dfDiag' not found

ERROR:root:Traceback (most recent call last):
  File "/home/grader/grade/133/hiro722722/final/check.py", line 76, in check
    result = eval(command, g)
  File "<string>", line 1, in <module>
  File "/usr/lib64/python2.7/site-packages/rpy2/robjects/__init__.py", line 240, in __call__
    res = self.eval(p)
  File "/usr/lib64/python2.7/site-packages/rpy2/robjects/functions.py", line 86, in __call__
    return super(SignatureTranslatedFunction, self).__call__(*args, **kwargs)
  File "/usr/lib64/python2.7/site-packages/rpy2/robjects/functions.py", line 35, in __call__
    res = super(Function, self).__call__(*new_args, **new_kwargs)
RRuntimeError: Error in all.equal(dfDiag$rawData, data) : object 'dfDiag' not found

Traceback (most recent call last):
  File "/home/grader/grade/133/hiro722722/final/check.py", line 76, in check
    result = eval(command, g)
  File "<string>", line 1, in <module>
  File "/usr/lib64/python2.7/site-packages/rpy2/robjects/__init__.py", line 240, in __call__
    res = self.eval(p)
  File "/usr/lib64/python2.7/site-packages/rpy2/robjects/functions.py", line 86, in __call__
    return super(SignatureTranslatedFunction, self).__call__(*args, **kwargs)
  File "/usr/lib64/python2.7/site-packages/rpy2/robjects/functions.py", line 35, in __call__
    res = super(Function, self).__call__(*new_args, **new_kwargs)
RRuntimeError: Error in all.equal(dfDiag$rawData, data) : object 'dfDiag' not found

ERROR:root:(3 points) Checking R('all.equal(dfDiag$thresholds, c(naR,naC))')[0]
ERROR:root:... Expecting: True
ERROR:root:... But got:   Traceback error
ERROR:root:Got exception:
Traceback (most recent call last):
  File "/home/grader/grade/133/hiro722722/final/check.py", line 76, in check
    result = eval(command, g)
  File "<string>", line 1, in <module>
  File "/usr/lib64/python2.7/site-packages/rpy2/robjects/__init__.py", line 240, in __call__
    res = self.eval(p)
  File "/usr/lib64/python2.7/site-packages/rpy2/robjects/functions.py", line 86, in __call__
    return super(SignatureTranslatedFunction, self).__call__(*args, **kwargs)
  File "/usr/lib64/python2.7/site-packages/rpy2/robjects/functions.py", line 35, in __call__
    res = super(Function, self).__call__(*new_args, **new_kwargs)
RRuntimeError: Error in all.equal(dfDiag$thresholds, c(naR, naC)) : 
  object 'dfDiag' not found

ERROR:root:Traceback (most recent call last):
  File "/home/grader/grade/133/hiro722722/final/check.py", line 76, in check
    result = eval(command, g)
  File "<string>", line 1, in <module>
  File "/usr/lib64/python2.7/site-packages/rpy2/robjects/__init__.py", line 240, in __call__
    res = self.eval(p)
  File "/usr/lib64/python2.7/site-packages/rpy2/robjects/functions.py", line 86, in __call__
    return super(SignatureTranslatedFunction, self).__call__(*args, **kwargs)
  File "/usr/lib64/python2.7/site-packages/rpy2/robjects/functions.py", line 35, in __call__
    res = super(Function, self).__call__(*new_args, **new_kwargs)
RRuntimeError: Error in all.equal(dfDiag$thresholds, c(naR, naC)) : 
  object 'dfDiag' not found

Traceback (most recent call last):
  File "/home/grader/grade/133/hiro722722/final/check.py", line 76, in check
    result = eval(command, g)
  File "<string>", line 1, in <module>
  File "/usr/lib64/python2.7/site-packages/rpy2/robjects/__init__.py", line 240, in __call__
    res = self.eval(p)
  File "/usr/lib64/python2.7/site-packages/rpy2/robjects/functions.py", line 86, in __call__
    return super(SignatureTranslatedFunction, self).__call__(*args, **kwargs)
  File "/usr/lib64/python2.7/site-packages/rpy2/robjects/functions.py", line 35, in __call__
    res = super(Function, self).__call__(*new_args, **new_kwargs)
RRuntimeError: Error in all.equal(dfDiag$thresholds, c(naR, naC)) : 
  object 'dfDiag' not found

ERROR:root:(3 points) Checking R('all.equal(dfDiag$badRows, 1000)')[0]
ERROR:root:... Expecting: True
ERROR:root:... But got:   Traceback error
ERROR:root:Got exception:
Traceback (most recent call last):
  File "/home/grader/grade/133/hiro722722/final/check.py", line 76, in check
    result = eval(command, g)
  File "<string>", line 1, in <module>
  File "/usr/lib64/python2.7/site-packages/rpy2/robjects/__init__.py", line 240, in __call__
    res = self.eval(p)
  File "/usr/lib64/python2.7/site-packages/rpy2/robjects/functions.py", line 86, in __call__
    return super(SignatureTranslatedFunction, self).__call__(*args, **kwargs)
  File "/usr/lib64/python2.7/site-packages/rpy2/robjects/functions.py", line 35, in __call__
    res = super(Function, self).__call__(*new_args, **new_kwargs)
RRuntimeError: Error in all.equal(dfDiag$badRows, 1000) : object 'dfDiag' not found

ERROR:root:Traceback (most recent call last):
  File "/home/grader/grade/133/hiro722722/final/check.py", line 76, in check
    result = eval(command, g)
  File "<string>", line 1, in <module>
  File "/usr/lib64/python2.7/site-packages/rpy2/robjects/__init__.py", line 240, in __call__
    res = self.eval(p)
  File "/usr/lib64/python2.7/site-packages/rpy2/robjects/functions.py", line 86, in __call__
    return super(SignatureTranslatedFunction, self).__call__(*args, **kwargs)
  File "/usr/lib64/python2.7/site-packages/rpy2/robjects/functions.py", line 35, in __call__
    res = super(Function, self).__call__(*new_args, **new_kwargs)
RRuntimeError: Error in all.equal(dfDiag$badRows, 1000) : object 'dfDiag' not found

Traceback (most recent call last):
  File "/home/grader/grade/133/hiro722722/final/check.py", line 76, in check
    result = eval(command, g)
  File "<string>", line 1, in <module>
  File "/usr/lib64/python2.7/site-packages/rpy2/robjects/__init__.py", line 240, in __call__
    res = self.eval(p)
  File "/usr/lib64/python2.7/site-packages/rpy2/robjects/functions.py", line 86, in __call__
    return super(SignatureTranslatedFunction, self).__call__(*args, **kwargs)
  File "/usr/lib64/python2.7/site-packages/rpy2/robjects/functions.py", line 35, in __call__
    res = super(Function, self).__call__(*new_args, **new_kwargs)
RRuntimeError: Error in all.equal(dfDiag$badRows, 1000) : object 'dfDiag' not found

ERROR:root:(3 points) Checking R('all.equal(dfDiag$badCols, c(2,3))')[0]
ERROR:root:... Expecting: True
ERROR:root:... But got:   Traceback error
ERROR:root:Got exception:
Traceback (most recent call last):
  File "/home/grader/grade/133/hiro722722/final/check.py", line 76, in check
    result = eval(command, g)
  File "<string>", line 1, in <module>
  File "/usr/lib64/python2.7/site-packages/rpy2/robjects/__init__.py", line 240, in __call__
    res = self.eval(p)
  File "/usr/lib64/python2.7/site-packages/rpy2/robjects/functions.py", line 86, in __call__
    return super(SignatureTranslatedFunction, self).__call__(*args, **kwargs)
  File "/usr/lib64/python2.7/site-packages/rpy2/robjects/functions.py", line 35, in __call__
    res = super(Function, self).__call__(*new_args, **new_kwargs)
RRuntimeError: Error in all.equal(dfDiag$badCols, c(2, 3)) : object 'dfDiag' not found

ERROR:root:Traceback (most recent call last):
  File "/home/grader/grade/133/hiro722722/final/check.py", line 76, in check
    result = eval(command, g)
  File "<string>", line 1, in <module>
  File "/usr/lib64/python2.7/site-packages/rpy2/robjects/__init__.py", line 240, in __call__
    res = self.eval(p)
  File "/usr/lib64/python2.7/site-packages/rpy2/robjects/functions.py", line 86, in __call__
    return super(SignatureTranslatedFunction, self).__call__(*args, **kwargs)
  File "/usr/lib64/python2.7/site-packages/rpy2/robjects/functions.py", line 35, in __call__
    res = super(Function, self).__call__(*new_args, **new_kwargs)
RRuntimeError: Error in all.equal(dfDiag$badCols, c(2, 3)) : object 'dfDiag' not found

Traceback (most recent call last):
  File "/home/grader/grade/133/hiro722722/final/check.py", line 76, in check
    result = eval(command, g)
  File "<string>", line 1, in <module>
  File "/usr/lib64/python2.7/site-packages/rpy2/robjects/__init__.py", line 240, in __call__
    res = self.eval(p)
  File "/usr/lib64/python2.7/site-packages/rpy2/robjects/functions.py", line 86, in __call__
    return super(SignatureTranslatedFunction, self).__call__(*args, **kwargs)
  File "/usr/lib64/python2.7/site-packages/rpy2/robjects/functions.py", line 35, in __call__
    res = super(Function, self).__call__(*new_args, **new_kwargs)
RRuntimeError: Error in all.equal(dfDiag$badCols, c(2, 3)) : object 'dfDiag' not found

ERROR:root:(3 points) Checking R('all.equal(dfDiag$outliers, list(c(1,1)))')[0]
ERROR:root:... Expecting: True
ERROR:root:... But got:   Traceback error
ERROR:root:Got exception:
Traceback (most recent call last):
  File "/home/grader/grade/133/hiro722722/final/check.py", line 76, in check
    result = eval(command, g)
  File "<string>", line 1, in <module>
  File "/usr/lib64/python2.7/site-packages/rpy2/robjects/__init__.py", line 240, in __call__
    res = self.eval(p)
  File "/usr/lib64/python2.7/site-packages/rpy2/robjects/functions.py", line 86, in __call__
    return super(SignatureTranslatedFunction, self).__call__(*args, **kwargs)
  File "/usr/lib64/python2.7/site-packages/rpy2/robjects/functions.py", line 35, in __call__
    res = super(Function, self).__call__(*new_args, **new_kwargs)
RRuntimeError: Error in all.equal(dfDiag$outliers, list(c(1, 1))) : 
  object 'dfDiag' not found

ERROR:root:Traceback (most recent call last):
  File "/home/grader/grade/133/hiro722722/final/check.py", line 76, in check
    result = eval(command, g)
  File "<string>", line 1, in <module>
  File "/usr/lib64/python2.7/site-packages/rpy2/robjects/__init__.py", line 240, in __call__
    res = self.eval(p)
  File "/usr/lib64/python2.7/site-packages/rpy2/robjects/functions.py", line 86, in __call__
    return super(SignatureTranslatedFunction, self).__call__(*args, **kwargs)
  File "/usr/lib64/python2.7/site-packages/rpy2/robjects/functions.py", line 35, in __call__
    res = super(Function, self).__call__(*new_args, **new_kwargs)
RRuntimeError: Error in all.equal(dfDiag$outliers, list(c(1, 1))) : 
  object 'dfDiag' not found

Traceback (most recent call last):
  File "/home/grader/grade/133/hiro722722/final/check.py", line 76, in check
    result = eval(command, g)
  File "<string>", line 1, in <module>
  File "/usr/lib64/python2.7/site-packages/rpy2/robjects/__init__.py", line 240, in __call__
    res = self.eval(p)
  File "/usr/lib64/python2.7/site-packages/rpy2/robjects/functions.py", line 86, in __call__
    return super(SignatureTranslatedFunction, self).__call__(*args, **kwargs)
  File "/usr/lib64/python2.7/site-packages/rpy2/robjects/functions.py", line 35, in __call__
    res = super(Function, self).__call__(*new_args, **new_kwargs)
RRuntimeError: Error in all.equal(dfDiag$outliers, list(c(1, 1))) : 
  object 'dfDiag' not found

ERROR:root:(3 points) Checking R('all.equal(dfDiag$cleanData, cleanData)')[0]
ERROR:root:... Expecting: True
ERROR:root:... But got:   Traceback error
ERROR:root:Got exception:
Traceback (most recent call last):
  File "/home/grader/grade/133/hiro722722/final/check.py", line 76, in check
    result = eval(command, g)
  File "<string>", line 1, in <module>
  File "/usr/lib64/python2.7/site-packages/rpy2/robjects/__init__.py", line 240, in __call__
    res = self.eval(p)
  File "/usr/lib64/python2.7/site-packages/rpy2/robjects/functions.py", line 86, in __call__
    return super(SignatureTranslatedFunction, self).__call__(*args, **kwargs)
  File "/usr/lib64/python2.7/site-packages/rpy2/robjects/functions.py", line 35, in __call__
    res = super(Function, self).__call__(*new_args, **new_kwargs)
RRuntimeError: Error in all.equal(dfDiag$cleanData, cleanData) : 
  object 'dfDiag' not found

ERROR:root:Traceback (most recent call last):
  File "/home/grader/grade/133/hiro722722/final/check.py", line 76, in check
    result = eval(command, g)
  File "<string>", line 1, in <module>
  File "/usr/lib64/python2.7/site-packages/rpy2/robjects/__init__.py", line 240, in __call__
    res = self.eval(p)
  File "/usr/lib64/python2.7/site-packages/rpy2/robjects/functions.py", line 86, in __call__
    return super(SignatureTranslatedFunction, self).__call__(*args, **kwargs)
  File "/usr/lib64/python2.7/site-packages/rpy2/robjects/functions.py", line 35, in __call__
    res = super(Function, self).__call__(*new_args, **new_kwargs)
RRuntimeError: Error in all.equal(dfDiag$cleanData, cleanData) : 
  object 'dfDiag' not found

Traceback (most recent call last):
  File "/home/grader/grade/133/hiro722722/final/check.py", line 76, in check
    result = eval(command, g)
  File "<string>", line 1, in <module>
  File "/usr/lib64/python2.7/site-packages/rpy2/robjects/__init__.py", line 240, in __call__
    res = self.eval(p)
  File "/usr/lib64/python2.7/site-packages/rpy2/robjects/functions.py", line 86, in __call__
    return super(SignatureTranslatedFunction, self).__call__(*args, **kwargs)
  File "/usr/lib64/python2.7/site-packages/rpy2/robjects/functions.py", line 35, in __call__
    res = super(Function, self).__call__(*new_args, **new_kwargs)
RRuntimeError: Error in all.equal(dfDiag$cleanData, cleanData) : 
  object 'dfDiag' not found

INFO:root:You got a 0 out of 24.
